Workbook
Name FOP_FUP_A550: "Gráfico 1"

Sheet seg (1)
A1: IDS - INDICADOR DE DESEMPENHO EM SEGURANÇA
A2: Local: | B2: CMPC | E2: Auditor Líder: | F2: HSE
A3: Contratada: | E3: Auditor: | F3: HSE
A4: Subcontratada: | E4: Data:
A5: Acompanhante: | E5: Hora: | G5: Nº de pessoas:
A6: GABARITO DE OBSERVAÇÃO
A7: USO DE EPI´S | C7: Qtd. | D7: Peso | E7: Comentário
A8: Capacete/Jugular | I8: =IF(COUNT(C8:D8)=1,"-->Verifique! Item QTDE ou PESO em branco","-") -> -
A9: Máscara Respiratória | I9: =IF(COUNT(C9:D9)=1,"-->Verifique! Item QTDE ou PESO em branco","-") -> -
A10: Óculos | I10: =IF(COUNT(C10:D10)=1,"-->Verifique! Item QTDE ou PESO em branco","-") -> -
A11: Protetor Facial | I11: =IF(COUNT(C11:D11)=1,"-->Verifique! Item QTDE ou PESO em branco","-") -> -
A12: Protetor Auricular | I12: =IF(COUNT(C12:D12)=1,"-->Verifique! Item QTDE ou PESO em branco","-") -> -
A13: Luvas | I13: =IF(COUNT(C13:D13)=1,"-->Verifique! Item QTDE ou PESO em branco","-") -> -
A14: Avental/jaleco | I14: =IF(COUNT(C14:D14)=1,"-->Verifique! Item QTDE ou PESO em branco","-") -> -
A15: Calçado de Segurança | I15: =IF(COUNT(C15:D15)=1,"-->Verifique! Item QTDE ou PESO em branco","-") -> -
A16: Cinto de Segurança | I16: =IF(COUNT(C16:D16)=1,"-->Verifique! Item QTDE ou PESO em branco","-") -> -
A17: Sub-total: | C17: =SUM(C8:C16) -> 0
A18: POSIÇÃO DAS PESSOAS | C18: Qtd. | D18: Peso | E18: Comentário
A19: Bater contra/Ser atingido por | I19: =IF(COUNT(C19:D19)=1,"-->Verifique! Item QTDE ou PESO em branco","-") -> -
A20: Ficar preso | I20: =IF(COUNT(C20:D20)=1,"-->Verifique! Item QTDE ou PESO em branco","-") -> -
A21: Risco de queda | I21: =IF(COUNT(C21:D21)=1,"-->Verifique! Item QTDE ou PESO em branco","-") -> -
A22: Risco de queimadura | I22: =IF(COUNT(C22:D22)=1,"-->Verifique! Item QTDE ou PESO em branco","-") -> -
A23: Risco de choque elétrico | I23: =IF(COUNT(C23:D23)=1,"-->Verifique! Item QTDE ou PESO em branco","-") -> -
A24: Inalar/Absorver contaminantes | I24: =IF(COUNT(C24:D24)=1,"-->Verifique! Item QTDE ou PESO em branco","-") -> -
A25: Trabalho Sobreposto | I25: =IF(COUNT(C25:D25)=1,"-->Verifique! Item QTDE ou PESO em branco","-") -> -
A26: Ingerir contaminantes | I26: =IF(COUNT(C26:D26)=1,"-->Verifique! Item QTDE ou PESO em branco","-") -> -
A27: Postura inadequada | I27: =IF(COUNT(C27:D27)=1,"-->Verifique! Item QTDE ou PESO em branco","-") -> -
A28: Esforço inadequado | I28: =IF(COUNT(C28:D28)=1,"-->Verifique! Item QTDE ou PESO em branco","-") -> -
A29: Sub-total: | C29: =SUM(C19:C28) -> 0
A30: AÇÃO QUANDO OBSERVADO | C30: Qtd. | D30: Peso | E30: Comentário
A31: Mudança de posição | I31: =IF(COUNT(C31:D31)=1,"-->Verifique! Item QTDE ou PESO em branco","-") -> -
A32: Paraliza a atividade | I32: =IF(COUNT(C32:D32)=1,"-->Verifique! Item QTDE ou PESO em branco","-") -> -
A33: Ajusta o EPI | I33: =IF(COUNT(C33:D33)=1,"-->Verifique! Item QTDE ou PESO em branco","-") -> -
A34: Adequa o serviço | I34: =IF(COUNT(C34:D34)=1,"-->Verifique! Item QTDE ou PESO em branco","-") -> -
A35: Sub-total: | C35: =SUM(C31:C34) -> 0
A36: PROCEDIMENTOS | C36: Qtd. | D36: Peso | E36: Comentário
A37: Inadequados | I37: =IF(COUNT(C37:D37)=1,"-->Verifique! Item QTDE ou PESO em branco","-") -> -
A38: Não existem procedimentos escritos | I38: =IF(COUNT(C38:D38)=1,"-->Verifique! Item QTDE ou PESO em branco","-") -> -
A39: Adequados e não são seguidos | I39: =IF(COUNT(C39:D39)=1,"-->Verifique! Item QTDE ou PESO em branco","-") -> -
A40: Sub-total: | C40: =SUM(C37:C39) -> 0
...

Sheet ter (1)
A1: IDS - INDICADOR DE DESEMPENHO EM SEGURANÇA
A2: Local: | B2: ='seg (1)'!B2 -> CMPC | E2: Auditor Líder: | F2: ='seg (1)'!F2 -> HSE
A3: Contratada: | B3: ='seg (1)'!B3 -> 0 | E3: Auditor:
A4: Subcontratada: | B4: ='seg (1)'!B4 -> 0 | E4: Data:
A5: Acompanhante: | B5: ='seg (1)'!B5 -> 0 | E5: Hora: | G5: Nº de pessoas:
A6: GABARITO DE OBSERVAÇÃO
A7: USO DE EPI´S | C7: Qtd. | D7: Peso | E7: Comentário
A8: Capacete/Jugular | I8: =IF(COUNT(C8:D8)=1,"-->Verifique! Item QTDE ou PESO em branco","-") -> -
A9: Máscara Respiratória | I9: =IF(COUNT(C9:D9)=1,"-->Verifique! Item QTDE ou PESO em branco","-") -> -
A10: Óculos | I10: =IF(COUNT(C10:D10)=1,"-->Verifique! Item QTDE ou PESO em branco","-") -> -
A11: Protetor Facial | I11: =IF(COUNT(C11:D11)=1,"-->Verifique! Item QTDE ou PESO em branco","-") -> -
A12: Protetor Auricular | I12: =IF(COUNT(C12:D12)=1,"-->Verifique! Item QTDE ou PESO em branco","-") -> -
A13: Luvas | I13: =IF(COUNT(C13:D13)=1,"-->Verifique! Item QTDE ou PESO em branco","-") -> -
A14: Avental/jaleco | I14: =IF(COUNT(C14:D14)=1,"-->Verifique! Item QTDE ou PESO em branco","-") -> -
A15: Calçado de Segurança | I15: =IF(COUNT(C15:D15)=1,"-->Verifique! Item QTDE ou PESO em branco","-") -> -
A16: Cinto de Segurança | I16: =IF(COUNT(C16:D16)=1,"-->Verifique! Item QTDE ou PESO em branco","-") -> -
A17: Sub-total: | C17: =SUM(C8:C16) -> 0
A18: POSIÇÃO DAS PESSOAS | C18: Qtd. | D18: Peso | E18: Comentário
A19: Bater contra/Ser atingido por | I19: =IF(COUNT(C19:D19)=1,"-->Verifique! Item QTDE ou PESO em branco","-") -> -
A20: Ficar preso | I20: =IF(COUNT(C20:D20)=1,"-->Verifique! Item QTDE ou PESO em branco","-") -> -
A21: Risco de queda | I21: =IF(COUNT(C21:D21)=1,"-->Verifique! Item QTDE ou PESO em branco","-") -> -
A22: Risco de queimadura | I22: =IF(COUNT(C22:D22)=1,"-->Verifique! Item QTDE ou PESO em branco","-") -> -
A23: Risco de choque elétrico | I23: =IF(COUNT(C23:D23)=1,"-->Verifique! Item QTDE ou PESO em branco","-") -> -
A24: Inalar/Absorver contaminantes | I24: =IF(COUNT(C24:D24)=1,"-->Verifique! Item QTDE ou PESO em branco","-") -> -
A25: Trabalho Sobreposto | I25: =IF(COUNT(C25:D25)=1,"-->Verifique! Item QTDE ou PESO em branco","-") -> -
A26: Ingerir contaminantes | I26: =IF(COUNT(C26:D26)=1,"-->Verifique! Item QTDE ou PESO em branco","-") -> -
A27: Postura inadequada | I27: =IF(COUNT(C27:D27)=1,"-->Verifique! Item QTDE ou PESO em branco","-") -> -
A28: Esforço inadequado | I28: =IF(COUNT(C28:D28)=1,"-->Verifique! Item QTDE ou PESO em branco","-") -> -
A29: Sub-total: | C29: =SUM(C19:C28) -> 0
A30: AÇÃO QUANDO OBSERVADO | C30: Qtd. | D30: Peso | E30: Comentário
A31: Mudança de posição | I31: =IF(COUNT(C31:D31)=1,"-->Verifique! Item QTDE ou PESO em branco","-") -> -
A32: Paraliza a atividade | I32: =IF(COUNT(C32:D32)=1,"-->Verifique! Item QTDE ou PESO em branco","-") -> -
A33: Ajusta o EPI | I33: =IF(COUNT(C33:D33)=1,"-->Verifique! Item QTDE ou PESO em branco","-") -> -
A34: Adequa o serviço | I34: =IF(COUNT(C34:D34)=1,"-->Verifique! Item QTDE ou PESO em branco","-") -> -
A35: Sub-total: | C35: =SUM(C31:C34) -> 0
A36: PROCEDIMENTOS | C36: Qtd. | D36: Peso | E36: Comentário
A37: Inadequados | I37: =IF(COUNT(C37:D37)=1,"-->Verifique! Item QTDE ou PESO em branco","-") -> -
A38: Não existem procedimentos escritos | I38: =IF(COUNT(C38:D38)=1,"-->Verifique! Item QTDE ou PESO em branco","-") -> -
A39: Adequados e não são seguidos | I39: =IF(COUNT(C39:D39)=1,"-->Verifique! Item QTDE ou PESO em branco","-") -> -
A40: Sub-total: | C40: =SUM(C37:C39) -> 0
...

Sheet qua (1)
A1: IDS - INDICADOR DE DESEMPENHO EM SEGURANÇA
A2: Local: | B2: ='seg (1)'!B2 -> CMPC | E2: Auditor Líder: | F2: ='seg (1)'!F2 -> HSE
A3: Contratada: | B3: ='seg (1)'!B3 -> 0 | E3: Auditor:
A4: Subcontratada: | B4: ='seg (1)'!B4 -> 0 | E4: Data:
A5: Acompanhante: | B5: ='seg (1)'!B5 -> 0 | E5: Hora: | G5: Nº de pessoas:
A6: GABARITO DE OBSERVAÇÃO
A7: USO DE EPI´S | C7: Qtd. | D7: Peso | E7: Comentário
A8: Capacete/Jugular | I8: =IF(COUNT(C8:D8)=1,"-->Verifique! Item QTDE ou PESO em branco","-") -> -
A9: Máscara Respiratória | I9: =IF(COUNT(C9:D9)=1,"-->Verifique! Item QTDE ou PESO em branco","-") -> -
A10: Óculos | I10: =IF(COUNT(C10:D10)=1,"-->Verifique! Item QTDE ou PESO em branco","-") -> -
A11: Protetor Facial | I11: =IF(COUNT(C11:D11)=1,"-->Verifique! Item QTDE ou PESO em branco","-") -> -
A12: Protetor Auricular | I12: =IF(COUNT(C12:D12)=1,"-->Verifique! Item QTDE ou PESO em branco","-") -> -
A13: Luvas | I13: =IF(COUNT(C13:D13)=1,"-->Verifique! Item QTDE ou PESO em branco","-") -> -
A14: Avental/jaleco | I14: =IF(COUNT(C14:D14)=1,"-->Verifique! Item QTDE ou PESO em branco","-") -> -
A15: Calçado de Segurança | I15: =IF(COUNT(C15:D15)=1,"-->Verifique! Item QTDE ou PESO em branco","-") -> -
A16: Cinto de Segurança | I16: =IF(COUNT(C16:D16)=1,"-->Verifique! Item QTDE ou PESO em branco","-") -> -
A17: Sub-total: | C17: =SUM(C8:C16) -> 0
A18: POSIÇÃO DAS PESSOAS | C18: Qtd. | D18: Peso | E18: Comentário
A19: Bater contra/Ser atingido por | I19: =IF(COUNT(C19:D19)=1,"-->Verifique! Item QTDE ou PESO em branco","-") -> -
A20: Ficar preso | I20: =IF(COUNT(C20:D20)=1,"-->Verifique! Item QTDE ou PESO em branco","-") -> -
A21: Risco de queda | I21: =IF(COUNT(C21:D21)=1,"-->Verifique! Item QTDE ou PESO em branco","-") -> -
A22: Risco de queimadura | I22: =IF(COUNT(C22:D22)=1,"-->Verifique! Item QTDE ou PESO em branco","-") -> -
A23: Risco de choque elétrico | I23: =IF(COUNT(C23:D23)=1,"-->Verifique! Item QTDE ou PESO em branco","-") -> -
A24: Inalar/Absorver contaminantes | I24: =IF(COUNT(C24:D24)=1,"-->Verifique! Item QTDE ou PESO em branco","-") -> -
A25: Trabalho Sobreposto | I25: =IF(COUNT(C25:D25)=1,"-->Verifique! Item QTDE ou PESO em branco","-") -> -
A26: Ingerir contaminantes | I26: =IF(COUNT(C26:D26)=1,"-->Verifique! Item QTDE ou PESO em branco","-") -> -
A27: Postura inadequada | I27: =IF(COUNT(C27:D27)=1,"-->Verifique! Item QTDE ou PESO em branco","-") -> -
A28: Esforço inadequado | I28: =IF(COUNT(C28:D28)=1,"-->Verifique! Item QTDE ou PESO em branco","-") -> -
A29: Sub-total: | C29: =SUM(C19:C28) -> 0
A30: AÇÃO QUANDO OBSERVADO | C30: Qtd. | D30: Peso | E30: Comentário
A31: Mudança de posição | I31: =IF(COUNT(C31:D31)=1,"-->Verifique! Item QTDE ou PESO em branco","-") -> -
A32: Paraliza a atividade | I32: =IF(COUNT(C32:D32)=1,"-->Verifique! Item QTDE ou PESO em branco","-") -> -
A33: Ajusta o EPI | I33: =IF(COUNT(C33:D33)=1,"-->Verifique! Item QTDE ou PESO em branco","-") -> -
A34: Adequa o serviço | I34: =IF(COUNT(C34:D34)=1,"-->Verifique! Item QTDE ou PESO em branco","-") -> -
A35: Sub-total: | C35: =SUM(C31:C34) -> 0
A36: PROCEDIMENTOS | C36: Qtd. | D36: Peso | E36: Comentário
A37: Inadequados | I37: =IF(COUNT(C37:D37)=1,"-->Verifique! Item QTDE ou PESO em branco","-") -> -
A38: Não existem procedimentos escritos | I38: =IF(COUNT(C38:D38)=1,"-->Verifique! Item QTDE ou PESO em branco","-") -> -
A39: Adequados e não são seguidos | I39: =IF(COUNT(C39:D39)=1,"-->Verifique! Item QTDE ou PESO em branco","-") -> -
A40: Sub-total: | C40: =SUM(C37:C39) -> 0
...

Sheet qui (1)
A1: IDS - INDICADOR DE DESEMPENHO EM SEGURANÇA
A2: Local: | B2: ='seg (1)'!B2 -> CMPC | E2: Auditor Líder: | F2: ='seg (1)'!F2 -> HSE
A3: Contratada: | B3: ='seg (1)'!B3 -> 0 | E3: Auditor:
A4: Subcontratada: | B4: ='seg (1)'!B4 -> 0 | E4: Data:
A5: Acompanhante: | B5: ='seg (1)'!B5 -> 0 | E5: Hora: | G5: Nº de pessoas:
A6: GABARITO DE OBSERVAÇÃO
A7: USO DE EPI´S | C7: Qtd. | D7: Peso | E7: Comentário
A8: Capacete/Jugular | I8: =IF(COUNT(C8:D8)=1,"-->Verifique! Item QTDE ou PESO em branco","-") -> -
A9: Máscara Respiratória | I9: =IF(COUNT(C9:D9)=1,"-->Verifique! Item QTDE ou PESO em branco","-") -> -
A10: Óculos | I10: =IF(COUNT(C10:D10)=1,"-->Verifique! Item QTDE ou PESO em branco","-") -> -
A11: Protetor Facial | I11: =IF(COUNT(C11:D11)=1,"-->Verifique! Item QTDE ou PESO em branco","-") -> -
A12: Protetor Auricular | I12: =IF(COUNT(C12:D12)=1,"-->Verifique! Item QTDE ou PESO em branco","-") -> -
A13: Luvas | I13: =IF(COUNT(C13:D13)=1,"-->Verifique! Item QTDE ou PESO em branco","-") -> -
A14: Avental/jaleco | I14: =IF(COUNT(C14:D14)=1,"-->Verifique! Item QTDE ou PESO em branco","-") -> -
A15: Calçado de Segurança | I15: =IF(COUNT(C15:D15)=1,"-->Verifique! Item QTDE ou PESO em branco","-") -> -
A16: Cinto de Segurança | I16: =IF(COUNT(C16:D16)=1,"-->Verifique! Item QTDE ou PESO em branco","-") -> -
A17: Sub-total: | C17: =SUM(C8:C16) -> 0
A18: POSIÇÃO DAS PESSOAS | C18: Qtd. | D18: Peso | E18: Comentário
A19: Bater contra/Ser atingido por | I19: =IF(COUNT(C19:D19)=1,"-->Verifique! Item QTDE ou PESO em branco","-") -> -
A20: Ficar preso | I20: =IF(COUNT(C20:D20)=1,"-->Verifique! Item QTDE ou PESO em branco","-") -> -
A21: Risco de queda | I21: =IF(COUNT(C21:D21)=1,"-->Verifique! Item QTDE ou PESO em branco","-") -> -
A22: Risco de queimadura | I22: =IF(COUNT(C22:D22)=1,"-->Verifique! Item QTDE ou PESO em branco","-") -> -
A23: Risco de choque elétrico | I23: =IF(COUNT(C23:D23)=1,"-->Verifique! Item QTDE ou PESO em branco","-") -> -
A24: Inalar/Absorver contaminantes | I24: =IF(COUNT(C24:D24)=1,"-->Verifique! Item QTDE ou PESO em branco","-") -> -
A25: Trabalho Sobreposto | I25: =IF(COUNT(C25:D25)=1,"-->Verifique! Item QTDE ou PESO em branco","-") -> -
A26: Ingerir contaminantes | I26: =IF(COUNT(C26:D26)=1,"-->Verifique! Item QTDE ou PESO em branco","-") -> -
A27: Postura inadequada | I27: =IF(COUNT(C27:D27)=1,"-->Verifique! Item QTDE ou PESO em branco","-") -> -
A28: Esforço inadequado | I28: =IF(COUNT(C28:D28)=1,"-->Verifique! Item QTDE ou PESO em branco","-") -> -
A29: Sub-total: | C29: =SUM(C19:C28) -> 0
A30: AÇÃO QUANDO OBSERVADO | C30: Qtd. | D30: Peso | E30: Comentário
A31: Mudança de posição | I31: =IF(COUNT(C31:D31)=1,"-->Verifique! Item QTDE ou PESO em branco","-") -> -
A32: Paraliza a atividade | I32: =IF(COUNT(C32:D32)=1,"-->Verifique! Item QTDE ou PESO em branco","-") -> -
A33: Ajusta o EPI | I33: =IF(COUNT(C33:D33)=1,"-->Verifique! Item QTDE ou PESO em branco","-") -> -
A34: Adequa o serviço | I34: =IF(COUNT(C34:D34)=1,"-->Verifique! Item QTDE ou PESO em branco","-") -> -
A35: Sub-total: | C35: =SUM(C31:C34) -> 0
A36: PROCEDIMENTOS | C36: Qtd. | D36: Peso | E36: Comentário
A37: Inadequados | I37: =IF(COUNT(C37:D37)=1,"-->Verifique! Item QTDE ou PESO em branco","-") -> -
A38: Não existem procedimentos escritos | I38: =IF(COUNT(C38:D38)=1,"-->Verifique! Item QTDE ou PESO em branco","-") -> -
A39: Adequados e não são seguidos | I39: =IF(COUNT(C39:D39)=1,"-->Verifique! Item QTDE ou PESO em branco","-") -> -
A40: Sub-total: | C40: =SUM(C37:C39) -> 0
...

Sheet sex (1)
A1: IDS - INDICADOR DE DESEMPENHO EM SEGURANÇA
A2: Local: | B2: ='seg (1)'!B2 -> CMPC | E2: Auditor Líder: | F2: ='seg (1)'!F2 -> HSE
A3: Contratada: | B3: ='seg (1)'!B3 -> 0 | E3: Auditor:
A4: Subcontratada: | B4: ='seg (1)'!B4 -> 0 | E4: Data:
A5: Acompanhante: | B5: ='seg (1)'!B5 -> 0 | E5: Hora: | G5: Nº de pessoas:
A6: GABARITO DE OBSERVAÇÃO
A7: USO DE EPI´S | C7: Qtd. | D7: Peso | E7: Comentário
A8: Capacete/Jugular | I8: =IF(COUNT(C8:D8)=1,"-->Verifique! Item QTDE ou PESO em branco","-") -> -
A9: Máscara Respiratória | I9: =IF(COUNT(C9:D9)=1,"-->Verifique! Item QTDE ou PESO em branco","-") -> -
A10: Óculos | I10: =IF(COUNT(C10:D10)=1,"-->Verifique! Item QTDE ou PESO em branco","-") -> -
A11: Protetor Facial | I11: =IF(COUNT(C11:D11)=1,"-->Verifique! Item QTDE ou PESO em branco","-") -> -
A12: Protetor Auricular | I12: =IF(COUNT(C12:D12)=1,"-->Verifique! Item QTDE ou PESO em branco","-") -> -
A13: Luvas | I13: =IF(COUNT(C13:D13)=1,"-->Verifique! Item QTDE ou PESO em branco","-") -> -
A14: Avental/jaleco | I14: =IF(COUNT(C14:D14)=1,"-->Verifique! Item QTDE ou PESO em branco","-") -> -
A15: Calçado de Segurança | I15: =IF(COUNT(C15:D15)=1,"-->Verifique! Item QTDE ou PESO em branco","-") -> -
A16: Cinto de Segurança | I16: =IF(COUNT(C16:D16)=1,"-->Verifique! Item QTDE ou PESO em branco","-") -> -
A17: Sub-total: | C17: =SUM(C8:C16) -> 0
A18: POSIÇÃO DAS PESSOAS | C18: Qtd. | D18: Peso | E18: Comentário
A19: Bater contra/Ser atingido por | I19: =IF(COUNT(C19:D19)=1,"-->Verifique! Item QTDE ou PESO em branco","-") -> -
A20: Ficar preso | I20: =IF(COUNT(C20:D20)=1,"-->Verifique! Item QTDE ou PESO em branco","-") -> -
A21: Risco de queda | I21: =IF(COUNT(C21:D21)=1,"-->Verifique! Item QTDE ou PESO em branco","-") -> -
A22: Risco de queimadura | I22: =IF(COUNT(C22:D22)=1,"-->Verifique! Item QTDE ou PESO em branco","-") -> -
A23: Risco de choque elétrico | I23: =IF(COUNT(C23:D23)=1,"-->Verifique! Item QTDE ou PESO em branco","-") -> -
A24: Inalar/Absorver contaminantes | I24: =IF(COUNT(C24:D24)=1,"-->Verifique! Item QTDE ou PESO em branco","-") -> -
A25: Trabalho Sobreposto | I25: =IF(COUNT(C25:D25)=1,"-->Verifique! Item QTDE ou PESO em branco","-") -> -
A26: Ingerir contaminantes | I26: =IF(COUNT(C26:D26)=1,"-->Verifique! Item QTDE ou PESO em branco","-") -> -
A27: Postura inadequada | I27: =IF(COUNT(C27:D27)=1,"-->Verifique! Item QTDE ou PESO em branco","-") -> -
A28: Esforço inadequado | I28: =IF(COUNT(C28:D28)=1,"-->Verifique! Item QTDE ou PESO em branco","-") -> -
A29: Sub-total: | C29: =SUM(C19:C28) -> 0
A30: AÇÃO QUANDO OBSERVADO | C30: Qtd. | D30: Peso | E30: Comentário
A31: Mudança de posição | I31: =IF(COUNT(C31:D31)=1,"-->Verifique! Item QTDE ou PESO em branco","-") -> -
A32: Paraliza a atividade | I32: =IF(COUNT(C32:D32)=1,"-->Verifique! Item QTDE ou PESO em branco","-") -> -
A33: Ajusta o EPI | I33: =IF(COUNT(C33:D33)=1,"-->Verifique! Item QTDE ou PESO em branco","-") -> -
A34: Adequa o serviço | I34: =IF(COUNT(C34:D34)=1,"-->Verifique! Item QTDE ou PESO em branco","-") -> -
A35: Sub-total: | C35: =SUM(C31:C34) -> 0
A36: PROCEDIMENTOS | C36: Qtd. | D36: Peso | E36: Comentário
A37: Inadequados | I37: =IF(COUNT(C37:D37)=1,"-->Verifique! Item QTDE ou PESO em branco","-") -> -
A38: Não existem procedimentos escritos | I38: =IF(COUNT(C38:D38)=1,"-->Verifique! Item QTDE ou PESO em branco","-") -> -
A39: Adequados e não são seguidos | I39: =IF(COUNT(C39:D39)=1,"-->Verifique! Item QTDE ou PESO em branco","-") -> -
A40: Sub-total: | C40: =SUM(C37:C39) -> 0
...

Sheet sab (1)
A1: IDS - INDICADOR DE DESEMPENHO EM SEGURANÇA
A2: Local: | B2: ='seg (1)'!B2 -> CMPC | E2: Auditor Líder: | F2: ='seg (1)'!F2 -> HSE
A3: Contratada: | B3: ='seg (1)'!B3 -> 0 | E3: Auditor:
A4: Subcontratada: | B4: ='seg (1)'!B4 -> 0 | E4: Data:
A5: Acompanhante: | B5: ='seg (1)'!B5 -> 0 | E5: Hora: | G5: Nº de pessoas:
A6: GABARITO DE OBSERVAÇÃO
A7: USO DE EPI´S | C7: Qtd. | D7: Peso | E7: Comentário
A8: Capacete/Jugular | I8: =IF(COUNT(C8:D8)=1,"-->Verifique! Item QTDE ou PESO em branco","-") -> -
A9: Máscara Respiratória | I9: =IF(COUNT(C9:D9)=1,"-->Verifique! Item QTDE ou PESO em branco","-") -> -
A10: Óculos | I10: =IF(COUNT(C10:D10)=1,"-->Verifique! Item QTDE ou PESO em branco","-") -> -
A11: Protetor Facial | I11: =IF(COUNT(C11:D11)=1,"-->Verifique! Item QTDE ou PESO em branco","-") -> -
A12: Protetor Auricular | I12: =IF(COUNT(C12:D12)=1,"-->Verifique! Item QTDE ou PESO em branco","-") -> -
A13: Luvas | I13: =IF(COUNT(C13:D13)=1,"-->Verifique! Item QTDE ou PESO em branco","-") -> -
A14: Avental/jaleco | I14: =IF(COUNT(C14:D14)=1,"-->Verifique! Item QTDE ou PESO em branco","-") -> -
A15: Calçado de Segurança | I15: =IF(COUNT(C15:D15)=1,"-->Verifique! Item QTDE ou PESO em branco","-") -> -
A16: Cinto de Segurança | I16: =IF(COUNT(C16:D16)=1,"-->Verifique! Item QTDE ou PESO em branco","-") -> -
A17: Sub-total: | C17: =SUM(C8:C16) -> 0
A18: POSIÇÃO DAS PESSOAS | C18: Qtd. | D18: Peso | E18: Comentário
A19: Bater contra/Ser atingido por | I19: =IF(COUNT(C19:D19)=1,"-->Verifique! Item QTDE ou PESO em branco","-") -> -
A20: Ficar preso | I20: =IF(COUNT(C20:D20)=1,"-->Verifique! Item QTDE ou PESO em branco","-") -> -
A21: Risco de queda | I21: =IF(COUNT(C21:D21)=1,"-->Verifique! Item QTDE ou PESO em branco","-") -> -
A22: Risco de queimadura | I22: =IF(COUNT(C22:D22)=1,"-->Verifique! Item QTDE ou PESO em branco","-") -> -
A23: Risco de choque elétrico | I23: =IF(COUNT(C23:D23)=1,"-->Verifique! Item QTDE ou PESO em branco","-") -> -
A24: Inalar/Absorver contaminantes | I24: =IF(COUNT(C24:D24)=1,"-->Verifique! Item QTDE ou PESO em branco","-") -> -
A25: Trabalho Sobreposto | I25: =IF(COUNT(C25:D25)=1,"-->Verifique! Item QTDE ou PESO em branco","-") -> -
A26: Ingerir contaminantes | I26: =IF(COUNT(C26:D26)=1,"-->Verifique! Item QTDE ou PESO em branco","-") -> -
A27: Postura inadequada | I27: =IF(COUNT(C27:D27)=1,"-->Verifique! Item QTDE ou PESO em branco","-") -> -
A28: Esforço inadequado | I28: =IF(COUNT(C28:D28)=1,"-->Verifique! Item QTDE ou PESO em branco","-") -> -
A29: Sub-total: | C29: =SUM(C19:C28) -> 0
A30: AÇÃO QUANDO OBSERVADO | C30: Qtd. | D30: Peso | E30: Comentário
A31: Mudança de posição | I31: =IF(COUNT(C31:D31)=1,"-->Verifique! Item QTDE ou PESO em branco","-") -> -
A32: Paraliza a atividade | I32: =IF(COUNT(C32:D32)=1,"-->Verifique! Item QTDE ou PESO em branco","-") -> -
A33: Ajusta o EPI | I33: =IF(COUNT(C33:D33)=1,"-->Verifique! Item QTDE ou PESO em branco","-") -> -
A34: Adequa o serviço | I34: =IF(COUNT(C34:D34)=1,"-->Verifique! Item QTDE ou PESO em branco","-") -> -
A35: Sub-total: | C35: =SUM(C31:C34) -> 0
A36: PROCEDIMENTOS | C36: Qtd. | D36: Peso | E36: Comentário
A37: Inadequados | I37: =IF(COUNT(C37:D37)=1,"-->Verifique! Item QTDE ou PESO em branco","-") -> -
A38: Não existem procedimentos escritos | I38: =IF(COUNT(C38:D38)=1,"-->Verifique! Item QTDE ou PESO em branco","-") -> -
A39: Adequados e não são seguidos | I39: =IF(COUNT(C39:D39)=1,"-->Verifique! Item QTDE ou PESO em branco","-") -> -
A40: Sub-total: | C40: =SUM(C37:C39) -> 0
...

Sheet seg (2)
A1: IDS - INDICADOR DE DESEMPENHO EM SEGURANÇA
A2: Local: | B2: ='seg (1)'!B2 -> CMPC | E2: Auditor Líder: | F2: ='seg (1)'!F2 -> HSE
A3: Contratada: | B3: ='seg (1)'!B3 -> 0 | E3: Auditor:
A4: Subcontratada: | B4: ='seg (1)'!B4 -> 0 | E4: Data:
A5: Acompanhante: | B5: ='seg (1)'!B5 -> 0 | E5: Hora: | G5: Nº de pessoas:
A6: GABARITO DE OBSERVAÇÃO
A7: USO DE EPI´S | C7: Qtd. | D7: Peso | E7: Comentário
A8: Capacete/Jugular | I8: =IF(COUNT(C8:D8)=1,"-->Verifique! Item QTDE ou PESO em branco","-") -> -
A9: Máscara Respiratória | I9: =IF(COUNT(C9:D9)=1,"-->Verifique! Item QTDE ou PESO em branco","-") -> -
A10: Óculos | I10: =IF(COUNT(C10:D10)=1,"-->Verifique! Item QTDE ou PESO em branco","-") -> -
A11: Protetor Facial | I11: =IF(COUNT(C11:D11)=1,"-->Verifique! Item QTDE ou PESO em branco","-") -> -
A12: Protetor Auricular | I12: =IF(COUNT(C12:D12)=1,"-->Verifique! Item QTDE ou PESO em branco","-") -> -
A13: Luvas | I13: =IF(COUNT(C13:D13)=1,"-->Verifique! Item QTDE ou PESO em branco","-") -> -
A14: Avental/jaleco | I14: =IF(COUNT(C14:D14)=1,"-->Verifique! Item QTDE ou PESO em branco","-") -> -
A15: Calçado de Segurança | I15: =IF(COUNT(C15:D15)=1,"-->Verifique! Item QTDE ou PESO em branco","-") -> -
A16: Cinto de Segurança | I16: =IF(COUNT(C16:D16)=1,"-->Verifique! Item QTDE ou PESO em branco","-") -> -
A17: Sub-total: | C17: =SUM(C8:C16) -> 0
A18: POSIÇÃO DAS PESSOAS | C18: Qtd. | D18: Peso | E18: Comentário
A19: Bater contra/Ser atingido por | I19: =IF(COUNT(C19:D19)=1,"-->Verifique! Item QTDE ou PESO em branco","-") -> -
A20: Ficar preso | I20: =IF(COUNT(C20:D20)=1,"-->Verifique! Item QTDE ou PESO em branco","-") -> -
A21: Risco de queda | I21: =IF(COUNT(C21:D21)=1,"-->Verifique! Item QTDE ou PESO em branco","-") -> -
A22: Risco de queimadura | I22: =IF(COUNT(C22:D22)=1,"-->Verifique! Item QTDE ou PESO em branco","-") -> -
A23: Risco de choque elétrico | I23: =IF(COUNT(C23:D23)=1,"-->Verifique! Item QTDE ou PESO em branco","-") -> -
A24: Inalar/Absorver contaminantes | I24: =IF(COUNT(C24:D24)=1,"-->Verifique! Item QTDE ou PESO em branco","-") -> -
A25: Trabalho Sobreposto | I25: =IF(COUNT(C25:D25)=1,"-->Verifique! Item QTDE ou PESO em branco","-") -> -
A26: Ingerir contaminantes | I26: =IF(COUNT(C26:D26)=1,"-->Verifique! Item QTDE ou PESO em branco","-") -> -
A27: Postura inadequada | I27: =IF(COUNT(C27:D27)=1,"-->Verifique! Item QTDE ou PESO em branco","-") -> -
A28: Esforço inadequado | I28: =IF(COUNT(C28:D28)=1,"-->Verifique! Item QTDE ou PESO em branco","-") -> -
A29: Sub-total: | C29: =SUM(C19:C28) -> 0
A30: AÇÃO QUANDO OBSERVADO | C30: Qtd. | D30: Peso | E30: Comentário
A31: Mudança de posição | I31: =IF(COUNT(C31:D31)=1,"-->Verifique! Item QTDE ou PESO em branco","-") -> -
A32: Paraliza a atividade | I32: =IF(COUNT(C32:D32)=1,"-->Verifique! Item QTDE ou PESO em branco","-") -> -
A33: Ajusta o EPI | I33: =IF(COUNT(C33:D33)=1,"-->Verifique! Item QTDE ou PESO em branco","-") -> -
A34: Adequa o serviço | I34: =IF(COUNT(C34:D34)=1,"-->Verifique! Item QTDE ou PESO em branco","-") -> -
A35: Sub-total: | C35: =SUM(C31:C34) -> 0
A36: PROCEDIMENTOS | C36: Qtd. | D36: Peso | E36: Comentário
A37: Inadequados | I37: =IF(COUNT(C37:D37)=1,"-->Verifique! Item QTDE ou PESO em branco","-") -> -
A38: Não existem procedimentos escritos | I38: =IF(COUNT(C38:D38)=1,"-->Verifique! Item QTDE ou PESO em branco","-") -> -
A39: Adequados e não são seguidos | I39: =IF(COUNT(C39:D39)=1,"-->Verifique! Item QTDE ou PESO em branco","-") -> -
A40: Sub-total: | C40: =SUM(C37:C39) -> 0
...

Sheet ter (2)
A1: IDS - INDICADOR DE DESEMPENHO EM SEGURANÇA
A2: Local: | B2: ='seg (1)'!B2 -> CMPC | E2: Auditor Líder: | F2: ='seg (1)'!F2 -> HSE
A3: Contratada: | B3: ='seg (1)'!B3 -> 0 | E3: Auditor:
A4: Subcontratada: | B4: ='seg (1)'!B4 -> 0 | E4: Data:
A5: Acompanhante: | B5: ='seg (1)'!B5 -> 0 | E5: Hora: | G5: Nº de pessoas:
A6: GABARITO DE OBSERVAÇÃO
A7: USO DE EPI´S | C7: Qtd. | D7: Peso | E7: Comentário
A8: Capacete/Jugular | I8: =IF(COUNT(C8:D8)=1,"-->Verifique! Item QTDE ou PESO em branco","-") -> -
A9: Máscara Respiratória | I9: =IF(COUNT(C9:D9)=1,"-->Verifique! Item QTDE ou PESO em branco","-") -> -
A10: Óculos | I10: =IF(COUNT(C10:D10)=1,"-->Verifique! Item QTDE ou PESO em branco","-") -> -
A11: Protetor Facial | I11: =IF(COUNT(C11:D11)=1,"-->Verifique! Item QTDE ou PESO em branco","-") -> -
A12: Protetor Auricular | I12: =IF(COUNT(C12:D12)=1,"-->Verifique! Item QTDE ou PESO em branco","-") -> -
A13: Luvas | I13: =IF(COUNT(C13:D13)=1,"-->Verifique! Item QTDE ou PESO em branco","-") -> -
A14: Avental/jaleco | I14: =IF(COUNT(C14:D14)=1,"-->Verifique! Item QTDE ou PESO em branco","-") -> -
A15: Calçado de Segurança | I15: =IF(COUNT(C15:D15)=1,"-->Verifique! Item QTDE ou PESO em branco","-") -> -
A16: Cinto de Segurança | I16: =IF(COUNT(C16:D16)=1,"-->Verifique! Item QTDE ou PESO em branco","-") -> -
A17: Sub-total: | C17: =SUM(C8:C16) -> 0
A18: POSIÇÃO DAS PESSOAS | C18: Qtd. | D18: Peso | E18: Comentário
A19: Bater contra/Ser atingido por | I19: =IF(COUNT(C19:D19)=1,"-->Verifique! Item QTDE ou PESO em branco","-") -> -
A20: Ficar preso | I20: =IF(COUNT(C20:D20)=1,"-->Verifique! Item QTDE ou PESO em branco","-") -> -
A21: Risco de queda | I21: =IF(COUNT(C21:D21)=1,"-->Verifique! Item QTDE ou PESO em branco","-") -> -
A22: Risco de queimadura | I22: =IF(COUNT(C22:D22)=1,"-->Verifique! Item QTDE ou PESO em branco","-") -> -
A23: Risco de choque elétrico | I23: =IF(COUNT(C23:D23)=1,"-->Verifique! Item QTDE ou PESO em branco","-") -> -
A24: Inalar/Absorver contaminantes | I24: =IF(COUNT(C24:D24)=1,"-->Verifique! Item QTDE ou PESO em branco","-") -> -
A25: Trabalho Sobreposto | I25: =IF(COUNT(C25:D25)=1,"-->Verifique! Item QTDE ou PESO em branco","-") -> -
A26: Ingerir contaminantes | I26: =IF(COUNT(C26:D26)=1,"-->Verifique! Item QTDE ou PESO em branco","-") -> -
A27: Postura inadequada | I27: =IF(COUNT(C27:D27)=1,"-->Verifique! Item QTDE ou PESO em branco","-") -> -
A28: Esforço inadequado | I28: =IF(COUNT(C28:D28)=1,"-->Verifique! Item QTDE ou PESO em branco","-") -> -
A29: Sub-total: | C29: =SUM(C19:C28) -> 0
A30: AÇÃO QUANDO OBSERVADO | C30: Qtd. | D30: Peso | E30: Comentário
A31: Mudança de posição | I31: =IF(COUNT(C31:D31)=1,"-->Verifique! Item QTDE ou PESO em branco","-") -> -
A32: Paraliza a atividade | I32: =IF(COUNT(C32:D32)=1,"-->Verifique! Item QTDE ou PESO em branco","-") -> -
A33: Ajusta o EPI | I33: =IF(COUNT(C33:D33)=1,"-->Verifique! Item QTDE ou PESO em branco","-") -> -
A34: Adequa o serviço | I34: =IF(COUNT(C34:D34)=1,"-->Verifique! Item QTDE ou PESO em branco","-") -> -
A35: Sub-total: | C35: =SUM(C31:C34) -> 0
A36: PROCEDIMENTOS | C36: Qtd. | D36: Peso | E36: Comentário
A37: Inadequados | I37: =IF(COUNT(C37:D37)=1,"-->Verifique! Item QTDE ou PESO em branco","-") -> -
A38: Não existem procedimentos escritos | I38: =IF(COUNT(C38:D38)=1,"-->Verifique! Item QTDE ou PESO em branco","-") -> -
A39: Adequados e não são seguidos | I39: =IF(COUNT(C39:D39)=1,"-->Verifique! Item QTDE ou PESO em branco","-") -> -
A40: Sub-total: | C40: =SUM(C37:C39) -> 0
...

Sheet qua (2)
A1: IDS - INDICADOR DE DESEMPENHO EM SEGURANÇA
A2: Local: | B2: ='seg (1)'!B2 -> CMPC | E2: Auditor Líder: | F2: ='seg (1)'!F2 -> HSE
A3: Contratada: | B3: ='seg (1)'!B3 -> 0 | E3: Auditor:
A4: Subcontratada: | B4: ='seg (1)'!B4 -> 0 | E4: Data:
A5: Acompanhante: | B5: ='seg (1)'!B5 -> 0 | E5: Hora: | G5: Nº de pessoas:
A6: GABARITO DE OBSERVAÇÃO
A7: USO DE EPI´S | C7: Qtd. | D7: Peso | E7: Comentário
A8: Capacete/Jugular | I8: =IF(COUNT(C8:D8)=1,"-->Verifique! Item QTDE ou PESO em branco","-") -> -
A9: Máscara Respiratória | I9: =IF(COUNT(C9:D9)=1,"-->Verifique! Item QTDE ou PESO em branco","-") -> -
A10: Óculos | I10: =IF(COUNT(C10:D10)=1,"-->Verifique! Item QTDE ou PESO em branco","-") -> -
A11: Protetor Facial | I11: =IF(COUNT(C11:D11)=1,"-->Verifique! Item QTDE ou PESO em branco","-") -> -
A12: Protetor Auricular | I12: =IF(COUNT(C12:D12)=1,"-->Verifique! Item QTDE ou PESO em branco","-") -> -
A13: Luvas | I13: =IF(COUNT(C13:D13)=1,"-->Verifique! Item QTDE ou PESO em branco","-") -> -
A14: Avental/jaleco | I14: =IF(COUNT(C14:D14)=1,"-->Verifique! Item QTDE ou PESO em branco","-") -> -
A15: Calçado de Segurança | I15: =IF(COUNT(C15:D15)=1,"-->Verifique! Item QTDE ou PESO em branco","-") -> -
A16: Cinto de Segurança | I16: =IF(COUNT(C16:D16)=1,"-->Verifique! Item QTDE ou PESO em branco","-") -> -
A17: Sub-total: | C17: =SUM(C8:C16) -> 0
A18: POSIÇÃO DAS PESSOAS | C18: Qtd. | D18: Peso | E18: Comentário
A19: Bater contra/Ser atingido por | I19: =IF(COUNT(C19:D19)=1,"-->Verifique! Item QTDE ou PESO em branco","-") -> -
A20: Ficar preso | I20: =IF(COUNT(C20:D20)=1,"-->Verifique! Item QTDE ou PESO em branco","-") -> -
A21: Risco de queda | I21: =IF(COUNT(C21:D21)=1,"-->Verifique! Item QTDE ou PESO em branco","-") -> -
A22: Risco de queimadura | I22: =IF(COUNT(C22:D22)=1,"-->Verifique! Item QTDE ou PESO em branco","-") -> -
A23: Risco de choque elétrico | I23: =IF(COUNT(C23:D23)=1,"-->Verifique! Item QTDE ou PESO em branco","-") -> -
A24: Inalar/Absorver contaminantes | I24: =IF(COUNT(C24:D24)=1,"-->Verifique! Item QTDE ou PESO em branco","-") -> -
A25: Trabalho Sobreposto | I25: =IF(COUNT(C25:D25)=1,"-->Verifique! Item QTDE ou PESO em branco","-") -> -
A26: Ingerir contaminantes | I26: =IF(COUNT(C26:D26)=1,"-->Verifique! Item QTDE ou PESO em branco","-") -> -
A27: Postura inadequada | I27: =IF(COUNT(C27:D27)=1,"-->Verifique! Item QTDE ou PESO em branco","-") -> -
A28: Esforço inadequado | I28: =IF(COUNT(C28:D28)=1,"-->Verifique! Item QTDE ou PESO em branco","-") -> -
A29: Sub-total: | C29: =SUM(C19:C28) -> 0
A30: AÇÃO QUANDO OBSERVADO | C30: Qtd. | D30: Peso | E30: Comentário
A31: Mudança de posição | I31: =IF(COUNT(C31:D31)=1,"-->Verifique! Item QTDE ou PESO em branco","-") -> -
A32: Paraliza a atividade | I32: =IF(COUNT(C32:D32)=1,"-->Verifique! Item QTDE ou PESO em branco","-") -> -
A33: Ajusta o EPI | I33: =IF(COUNT(C33:D33)=1,"-->Verifique! Item QTDE ou PESO em branco","-") -> -
A34: Adequa o serviço | I34: =IF(COUNT(C34:D34)=1,"-->Verifique! Item QTDE ou PESO em branco","-") -> -
A35: Sub-total: | C35: =SUM(C31:C34) -> 0
A36: PROCEDIMENTOS | C36: Qtd. | D36: Peso | E36: Comentário
A37: Inadequados | I37: =IF(COUNT(C37:D37)=1,"-->Verifique! Item QTDE ou PESO em branco","-") -> -
A38: Não existem procedimentos escritos | I38: =IF(COUNT(C38:D38)=1,"-->Verifique! Item QTDE ou PESO em branco","-") -> -
A39: Adequados e não são seguidos | I39: =IF(COUNT(C39:D39)=1,"-->Verifique! Item QTDE ou PESO em branco","-") -> -
A40: Sub-total: | C40: =SUM(C37:C39) -> 0
...

Sheet qui (2)
A1: IDS - INDICADOR DE DESEMPENHO EM SEGURANÇA
A2: Local: | B2: CMPC | E2: Auditor Líder:
A3: Contratada: | E3: Auditor:
A4: Subcontratada: | E4: Data:
A5: Acompanhante: | E5: Hora: | G5: Nº de pessoas:
A6: GABARITO DE OBSERVAÇÃO
A7: USO DE EPI´S | C7: Qtd. | D7: Peso | E7: Comentário
A8: Capacete/Jugular | I8: =IF(COUNT(C8:D8)=1,"-->Verifique! Item QTDE ou PESO em branco","-") -> -
A9: Máscara Respiratória | I9: =IF(COUNT(C9:D9)=1,"-->Verifique! Item QTDE ou PESO em branco","-") -> -
A10: Óculos | I10: =IF(COUNT(C10:D10)=1,"-->Verifique! Item QTDE ou PESO em branco","-") -> -
A11: Protetor Facial | I11: =IF(COUNT(C11:D11)=1,"-->Verifique! Item QTDE ou PESO em branco","-") -> -
A12: Protetor Auricular | I12: =IF(COUNT(C12:D12)=1,"-->Verifique! Item QTDE ou PESO em branco","-") -> -
A13: Luvas | I13: =IF(COUNT(C13:D13)=1,"-->Verifique! Item QTDE ou PESO em branco","-") -> -
A14: Avental/jaleco | I14: =IF(COUNT(C14:D14)=1,"-->Verifique! Item QTDE ou PESO em branco","-") -> -
A15: Calçado de Segurança | I15: =IF(COUNT(C15:D15)=1,"-->Verifique! Item QTDE ou PESO em branco","-") -> -
A16: Cinto de Segurança | I16: =IF(COUNT(C16:D16)=1,"-->Verifique! Item QTDE ou PESO em branco","-") -> -
A17: Sub-total: | C17: =SUM(C8:C16) -> 0
A18: POSIÇÃO DAS PESSOAS | C18: Qtd. | D18: Peso | E18: Comentário
A19: Bater contra/Ser atingido por | I19: =IF(COUNT(C19:D19)=1,"-->Verifique! Item QTDE ou PESO em branco","-") -> -
A20: Ficar preso | I20: =IF(COUNT(C20:D20)=1,"-->Verifique! Item QTDE ou PESO em branco","-") -> -
A21: Risco de queda | I21: =IF(COUNT(C21:D21)=1,"-->Verifique! Item QTDE ou PESO em branco","-") -> -
A22: Risco de queimadura | I22: =IF(COUNT(C22:D22)=1,"-->Verifique! Item QTDE ou PESO em branco","-") -> -
A23: Risco de choque elétrico | I23: =IF(COUNT(C23:D23)=1,"-->Verifique! Item QTDE ou PESO em branco","-") -> -
A24: Inalar/Absorver contaminantes | I24: =IF(COUNT(C24:D24)=1,"-->Verifique! Item QTDE ou PESO em branco","-") -> -
A25: Trabalho Sobreposto | I25: =IF(COUNT(C25:D25)=1,"-->Verifique! Item QTDE ou PESO em branco","-") -> -
A26: Ingerir contaminantes | I26: =IF(COUNT(C26:D26)=1,"-->Verifique! Item QTDE ou PESO em branco","-") -> -
A27: Postura inadequada | I27: =IF(COUNT(C27:D27)=1,"-->Verifique! Item QTDE ou PESO em branco","-") -> -
A28: Esforço inadequado | I28: =IF(COUNT(C28:D28)=1,"-->Verifique! Item QTDE ou PESO em branco","-") -> -
A29: Sub-total: | C29: =SUM(C19:C28) -> 0
A30: AÇÃO QUANDO OBSERVADO | C30: Qtd. | D30: Peso | E30: Comentário
A31: Mudança de posição | I31: =IF(COUNT(C31:D31)=1,"-->Verifique! Item QTDE ou PESO em branco","-") -> -
A32: Paraliza a atividade | I32: =IF(COUNT(C32:D32)=1,"-->Verifique! Item QTDE ou PESO em branco","-") -> -
A33: Ajusta o EPI | I33: =IF(COUNT(C33:D33)=1,"-->Verifique! Item QTDE ou PESO em branco","-") -> -
A34: Adequa o serviço | I34: =IF(COUNT(C34:D34)=1,"-->Verifique! Item QTDE ou PESO em branco","-") -> -
A35: Sub-total: | C35: =SUM(C31:C34) -> 0
A36: PROCEDIMENTOS | C36: Qtd. | D36: Peso | E36: Comentário
A37: Inadequados | I37: =IF(COUNT(C37:D37)=1,"-->Verifique! Item QTDE ou PESO em branco","-") -> -
A38: Não existem procedimentos escritos | I38: =IF(COUNT(C38:D38)=1,"-->Verifique! Item QTDE ou PESO em branco","-") -> -
A39: Adequados e não são seguidos | I39: =IF(COUNT(C39:D39)=1,"-->Verifique! Item QTDE ou PESO em branco","-") -> -
A40: Sub-total: | C40: =SUM(C37:C39) -> 0
...

Sheet sex (2)
A1: IDS - INDICADOR DE DESEMPENHO EM SEGURANÇA
A2: Local: | B2: CMPC | E2: Auditor Líder:
A3: Contratada: | E3: Auditor:
A4: Subcontratada: | E4: Data:
A5: Acompanhante: | E5: Hora: | G5: Nº de pessoas:
A6: GABARITO DE OBSERVAÇÃO
A7: USO DE EPI´S | C7: Qtd. | D7: Peso | E7: Comentário
A8: Capacete/Jugular | I8: =IF(COUNT(C8:D8)=1,"-->Verifique! Item QTDE ou PESO em branco","-") -> -
A9: Máscara Respiratória | I9: =IF(COUNT(C9:D9)=1,"-->Verifique! Item QTDE ou PESO em branco","-") -> -
A10: Óculos | I10: =IF(COUNT(C10:D10)=1,"-->Verifique! Item QTDE ou PESO em branco","-") -> -
A11: Protetor Facial | I11: =IF(COUNT(C11:D11)=1,"-->Verifique! Item QTDE ou PESO em branco","-") -> -
A12: Protetor Auricular | I12: =IF(COUNT(C12:D12)=1,"-->Verifique! Item QTDE ou PESO em branco","-") -> -
A13: Luvas | I13: =IF(COUNT(C13:D13)=1,"-->Verifique! Item QTDE ou PESO em branco","-") -> -
A14: Avental/jaleco | I14: =IF(COUNT(C14:D14)=1,"-->Verifique! Item QTDE ou PESO em branco","-") -> -
A15: Calçado de Segurança | I15: =IF(COUNT(C15:D15)=1,"-->Verifique! Item QTDE ou PESO em branco","-") -> -
A16: Cinto de Segurança | I16: =IF(COUNT(C16:D16)=1,"-->Verifique! Item QTDE ou PESO em branco","-") -> -
A17: Sub-total: | C17: =SUM(C8:C16) -> 0
A18: POSIÇÃO DAS PESSOAS | C18: Qtd. | D18: Peso | E18: Comentário
A19: Bater contra/Ser atingido por | I19: =IF(COUNT(C19:D19)=1,"-->Verifique! Item QTDE ou PESO em branco","-") -> -
A20: Ficar preso | I20: =IF(COUNT(C20:D20)=1,"-->Verifique! Item QTDE ou PESO em branco","-") -> -
A21: Risco de queda | I21: =IF(COUNT(C21:D21)=1,"-->Verifique! Item QTDE ou PESO em branco","-") -> -
A22: Risco de queimadura | I22: =IF(COUNT(C22:D22)=1,"-->Verifique! Item QTDE ou PESO em branco","-") -> -
A23: Risco de choque elétrico | I23: =IF(COUNT(C23:D23)=1,"-->Verifique! Item QTDE ou PESO em branco","-") -> -
A24: Inalar/Absorver contaminantes | I24: =IF(COUNT(C24:D24)=1,"-->Verifique! Item QTDE ou PESO em branco","-") -> -
A25: Trabalho Sobreposto | I25: =IF(COUNT(C25:D25)=1,"-->Verifique! Item QTDE ou PESO em branco","-") -> -
A26: Ingerir contaminantes | I26: =IF(COUNT(C26:D26)=1,"-->Verifique! Item QTDE ou PESO em branco","-") -> -
A27: Postura inadequada | I27: =IF(COUNT(C27:D27)=1,"-->Verifique! Item QTDE ou PESO em branco","-") -> -
A28: Esforço inadequado | I28: =IF(COUNT(C28:D28)=1,"-->Verifique! Item QTDE ou PESO em branco","-") -> -
A29: Sub-total: | C29: =SUM(C19:C28) -> 0
A30: AÇÃO QUANDO OBSERVADO | C30: Qtd. | D30: Peso | E30: Comentário
A31: Mudança de posição | I31: =IF(COUNT(C31:D31)=1,"-->Verifique! Item QTDE ou PESO em branco","-") -> -
A32: Paraliza a atividade | I32: =IF(COUNT(C32:D32)=1,"-->Verifique! Item QTDE ou PESO em branco","-") -> -
A33: Ajusta o EPI | I33: =IF(COUNT(C33:D33)=1,"-->Verifique! Item QTDE ou PESO em branco","-") -> -
A34: Adequa o serviço | I34: =IF(COUNT(C34:D34)=1,"-->Verifique! Item QTDE ou PESO em branco","-") -> -
A35: Sub-total: | C35: =SUM(C31:C34) -> 0
A36: PROCEDIMENTOS | C36: Qtd. | D36: Peso | E36: Comentário
A37: Inadequados | I37: =IF(COUNT(C37:D37)=1,"-->Verifique! Item QTDE ou PESO em branco","-") -> -
A38: Não existem procedimentos escritos | I38: =IF(COUNT(C38:D38)=1,"-->Verifique! Item QTDE ou PESO em branco","-") -> -
A39: Adequados e não são seguidos | I39: =IF(COUNT(C39:D39)=1,"-->Verifique! Item QTDE ou PESO em branco","-") -> -
A40: Sub-total: | C40: =SUM(C37:C39) -> 0
...

Sheet sab (2)
A1: IDS - INDICADOR DE DESEMPENHO EM SEGURANÇA
A2: Local: | B2: ='seg (1)'!B2 -> CMPC | E2: Auditor Líder: | F2: ='seg (1)'!F2 -> HSE
A3: Contratada: | B3: ='seg (1)'!B3 -> 0 | E3: Auditor:
A4: Subcontratada: | B4: ='seg (1)'!B4 -> 0 | E4: Data:
A5: Acompanhante: | B5: ='seg (1)'!B5 -> 0 | E5: Hora: | G5: Nº de pessoas:
A6: GABARITO DE OBSERVAÇÃO
A7: USO DE EPI´S | C7: Qtd. | D7: Peso | E7: Comentário
A8: Capacete/Jugular | I8: =IF(COUNT(C8:D8)=1,"-->Verifique! Item QTDE ou PESO em branco","-") -> -
A9: Máscara Respiratória | I9: =IF(COUNT(C9:D9)=1,"-->Verifique! Item QTDE ou PESO em branco","-") -> -
A10: Óculos | I10: =IF(COUNT(C10:D10)=1,"-->Verifique! Item QTDE ou PESO em branco","-") -> -
A11: Protetor Facial | I11: =IF(COUNT(C11:D11)=1,"-->Verifique! Item QTDE ou PESO em branco","-") -> -
A12: Protetor Auricular | I12: =IF(COUNT(C12:D12)=1,"-->Verifique! Item QTDE ou PESO em branco","-") -> -
A13: Luvas | I13: =IF(COUNT(C13:D13)=1,"-->Verifique! Item QTDE ou PESO em branco","-") -> -
A14: Avental/jaleco | I14: =IF(COUNT(C14:D14)=1,"-->Verifique! Item QTDE ou PESO em branco","-") -> -
A15: Calçado de Segurança | I15: =IF(COUNT(C15:D15)=1,"-->Verifique! Item QTDE ou PESO em branco","-") -> -
A16: Cinto de Segurança | I16: =IF(COUNT(C16:D16)=1,"-->Verifique! Item QTDE ou PESO em branco","-") -> -
A17: Sub-total: | C17: =SUM(C8:C16) -> 0
A18: POSIÇÃO DAS PESSOAS | C18: Qtd. | D18: Peso | E18: Comentário
A19: Bater contra/Ser atingido por | I19: =IF(COUNT(C19:D19)=1,"-->Verifique! Item QTDE ou PESO em branco","-") -> -
A20: Ficar preso | I20: =IF(COUNT(C20:D20)=1,"-->Verifique! Item QTDE ou PESO em branco","-") -> -
A21: Risco de queda | I21: =IF(COUNT(C21:D21)=1,"-->Verifique! Item QTDE ou PESO em branco","-") -> -
A22: Risco de queimadura | I22: =IF(COUNT(C22:D22)=1,"-->Verifique! Item QTDE ou PESO em branco","-") -> -
A23: Risco de choque elétrico | I23: =IF(COUNT(C23:D23)=1,"-->Verifique! Item QTDE ou PESO em branco","-") -> -
A24: Inalar/Absorver contaminantes | I24: =IF(COUNT(C24:D24)=1,"-->Verifique! Item QTDE ou PESO em branco","-") -> -
A25: Trabalho Sobreposto | I25: =IF(COUNT(C25:D25)=1,"-->Verifique! Item QTDE ou PESO em branco","-") -> -
A26: Ingerir contaminantes | I26: =IF(COUNT(C26:D26)=1,"-->Verifique! Item QTDE ou PESO em branco","-") -> -
A27: Postura inadequada | I27: =IF(COUNT(C27:D27)=1,"-->Verifique! Item QTDE ou PESO em branco","-") -> -
A28: Esforço inadequado | I28: =IF(COUNT(C28:D28)=1,"-->Verifique! Item QTDE ou PESO em branco","-") -> -
A29: Sub-total: | C29: =SUM(C19:C28) -> 0
A30: AÇÃO QUANDO OBSERVADO | C30: Qtd. | D30: Peso | E30: Comentário
A31: Mudança de posição | I31: =IF(COUNT(C31:D31)=1,"-->Verifique! Item QTDE ou PESO em branco","-") -> -
A32: Paraliza a atividade | I32: =IF(COUNT(C32:D32)=1,"-->Verifique! Item QTDE ou PESO em branco","-") -> -
A33: Ajusta o EPI | I33: =IF(COUNT(C33:D33)=1,"-->Verifique! Item QTDE ou PESO em branco","-") -> -
A34: Adequa o serviço | I34: =IF(COUNT(C34:D34)=1,"-->Verifique! Item QTDE ou PESO em branco","-") -> -
A35: Sub-total: | C35: =SUM(C31:C34) -> 0
A36: PROCEDIMENTOS | C36: Qtd. | D36: Peso | E36: Comentário
A37: Inadequados | I37: =IF(COUNT(C37:D37)=1,"-->Verifique! Item QTDE ou PESO em branco","-") -> -
A38: Não existem procedimentos escritos | I38: =IF(COUNT(C38:D38)=1,"-->Verifique! Item QTDE ou PESO em branco","-") -> -
A39: Adequados e não são seguidos | I39: =IF(COUNT(C39:D39)=1,"-->Verifique! Item QTDE ou PESO em branco","-") -> -
A40: Sub-total: | C40: =SUM(C37:C39) -> 0
...

Sheet seg (3)
A1: IDS - INDICADOR DE DESEMPENHO EM SEGURANÇA
A2: Local: | B2: ='seg (1)'!B2 -> CMPC | E2: Auditor Líder: | F2: ='seg (1)'!F2 -> HSE
A3: Contratada: | B3: ='seg (1)'!B3 -> 0 | E3: Auditor:
A4: Subcontratada: | B4: ='seg (1)'!B4 -> 0 | E4: Data:
A5: Acompanhante: | B5: ='seg (1)'!B5 -> 0 | E5: Hora: | G5: Nº de pessoas:
A6: GABARITO DE OBSERVAÇÃO
A7: USO DE EPI´S | C7: Qtd. | D7: Peso | E7: Comentário
A8: Capacete/Jugular | I8: =IF(COUNT(C8:D8)=1,"-->Verifique! Item QTDE ou PESO em branco","-") -> -
A9: Máscara Respiratória | I9: =IF(COUNT(C9:D9)=1,"-->Verifique! Item QTDE ou PESO em branco","-") -> -
A10: Óculos | I10: =IF(COUNT(C10:D10)=1,"-->Verifique! Item QTDE ou PESO em branco","-") -> -
A11: Protetor Facial | I11: =IF(COUNT(C11:D11)=1,"-->Verifique! Item QTDE ou PESO em branco","-") -> -
A12: Protetor Auricular | I12: =IF(COUNT(C12:D12)=1,"-->Verifique! Item QTDE ou PESO em branco","-") -> -
A13: Luvas | I13: =IF(COUNT(C13:D13)=1,"-->Verifique! Item QTDE ou PESO em branco","-") -> -
A14: Avental/jaleco | I14: =IF(COUNT(C14:D14)=1,"-->Verifique! Item QTDE ou PESO em branco","-") -> -
A15: Calçado de Segurança | I15: =IF(COUNT(C15:D15)=1,"-->Verifique! Item QTDE ou PESO em branco","-") -> -
A16: Cinto de Segurança | I16: =IF(COUNT(C16:D16)=1,"-->Verifique! Item QTDE ou PESO em branco","-") -> -
A17: Sub-total: | C17: =SUM(C8:C16) -> 0
A18: POSIÇÃO DAS PESSOAS | C18: Qtd. | D18: Peso | E18: Comentário
A19: Bater contra/Ser atingido por | I19: =IF(COUNT(C19:D19)=1,"-->Verifique! Item QTDE ou PESO em branco","-") -> -
A20: Ficar preso | I20: =IF(COUNT(C20:D20)=1,"-->Verifique! Item QTDE ou PESO em branco","-") -> -
A21: Risco de queda | I21: =IF(COUNT(C21:D21)=1,"-->Verifique! Item QTDE ou PESO em branco","-") -> -
A22: Risco de queimadura | I22: =IF(COUNT(C22:D22)=1,"-->Verifique! Item QTDE ou PESO em branco","-") -> -
A23: Risco de choque elétrico | I23: =IF(COUNT(C23:D23)=1,"-->Verifique! Item QTDE ou PESO em branco","-") -> -
A24: Inalar/Absorver contaminantes | I24: =IF(COUNT(C24:D24)=1,"-->Verifique! Item QTDE ou PESO em branco","-") -> -
A25: Trabalho Sobreposto | I25: =IF(COUNT(C25:D25)=1,"-->Verifique! Item QTDE ou PESO em branco","-") -> -
A26: Ingerir contaminantes | I26: =IF(COUNT(C26:D26)=1,"-->Verifique! Item QTDE ou PESO em branco","-") -> -
A27: Postura inadequada | I27: =IF(COUNT(C27:D27)=1,"-->Verifique! Item QTDE ou PESO em branco","-") -> -
A28: Esforço inadequado | I28: =IF(COUNT(C28:D28)=1,"-->Verifique! Item QTDE ou PESO em branco","-") -> -
A29: Sub-total: | C29: =SUM(C19:C28) -> 0
A30: AÇÃO QUANDO OBSERVADO | C30: Qtd. | D30: Peso | E30: Comentário
A31: Mudança de posição | I31: =IF(COUNT(C31:D31)=1,"-->Verifique! Item QTDE ou PESO em branco","-") -> -
A32: Paraliza a atividade | I32: =IF(COUNT(C32:D32)=1,"-->Verifique! Item QTDE ou PESO em branco","-") -> -
A33: Ajusta o EPI | I33: =IF(COUNT(C33:D33)=1,"-->Verifique! Item QTDE ou PESO em branco","-") -> -
A34: Adequa o serviço | I34: =IF(COUNT(C34:D34)=1,"-->Verifique! Item QTDE ou PESO em branco","-") -> -
A35: Sub-total: | C35: =SUM(C31:C34) -> 0
A36: PROCEDIMENTOS | C36: Qtd. | D36: Peso | E36: Comentário
A37: Inadequados | I37: =IF(COUNT(C37:D37)=1,"-->Verifique! Item QTDE ou PESO em branco","-") -> -
A38: Não existem procedimentos escritos | I38: =IF(COUNT(C38:D38)=1,"-->Verifique! Item QTDE ou PESO em branco","-") -> -
A39: Adequados e não são seguidos | I39: =IF(COUNT(C39:D39)=1,"-->Verifique! Item QTDE ou PESO em branco","-") -> -
A40: Sub-total: | C40: =SUM(C37:C39) -> 0
...

Sheet ter (3)
A1: IDS - INDICADOR DE DESEMPENHO EM SEGURANÇA
A2: Local: | B2: ='seg (1)'!B2 -> CMPC | E2: Auditor Líder: | F2: ='seg (1)'!F2 -> HSE
A3: Contratada: | B3: ='seg (1)'!B3 -> 0 | E3: Auditor:
A4: Subcontratada: | B4: ='seg (1)'!B4 -> 0 | E4: Data:
A5: Acompanhante: | B5: ='seg (1)'!B5 -> 0 | E5: Hora: | G5: Nº de pessoas:
A6: GABARITO DE OBSERVAÇÃO
A7: USO DE EPI´S | C7: Qtd. | D7: Peso | E7: Comentário
A8: Capacete/Jugular | I8: =IF(COUNT(C8:D8)=1,"-->Verifique! Item QTDE ou PESO em branco","-") -> -
A9: Máscara Respiratória | I9: =IF(COUNT(C9:D9)=1,"-->Verifique! Item QTDE ou PESO em branco","-") -> -
A10: Óculos | I10: =IF(COUNT(C10:D10)=1,"-->Verifique! Item QTDE ou PESO em branco","-") -> -
A11: Protetor Facial | I11: =IF(COUNT(C11:D11)=1,"-->Verifique! Item QTDE ou PESO em branco","-") -> -
A12: Protetor Auricular | I12: =IF(COUNT(C12:D12)=1,"-->Verifique! Item QTDE ou PESO em branco","-") -> -
A13: Luvas | I13: =IF(COUNT(C13:D13)=1,"-->Verifique! Item QTDE ou PESO em branco","-") -> -
A14: Avental/jaleco | I14: =IF(COUNT(C14:D14)=1,"-->Verifique! Item QTDE ou PESO em branco","-") -> -
A15: Calçado de Segurança | I15: =IF(COUNT(C15:D15)=1,"-->Verifique! Item QTDE ou PESO em branco","-") -> -
A16: Cinto de Segurança | I16: =IF(COUNT(C16:D16)=1,"-->Verifique! Item QTDE ou PESO em branco","-") -> -
A17: Sub-total: | C17: =SUM(C8:C16) -> 0
A18: POSIÇÃO DAS PESSOAS | C18: Qtd. | D18: Peso | E18: Comentário
A19: Bater contra/Ser atingido por | I19: =IF(COUNT(C19:D19)=1,"-->Verifique! Item QTDE ou PESO em branco","-") -> -
A20: Ficar preso | I20: =IF(COUNT(C20:D20)=1,"-->Verifique! Item QTDE ou PESO em branco","-") -> -
A21: Risco de queda | I21: =IF(COUNT(C21:D21)=1,"-->Verifique! Item QTDE ou PESO em branco","-") -> -
A22: Risco de queimadura | I22: =IF(COUNT(C22:D22)=1,"-->Verifique! Item QTDE ou PESO em branco","-") -> -
A23: Risco de choque elétrico | I23: =IF(COUNT(C23:D23)=1,"-->Verifique! Item QTDE ou PESO em branco","-") -> -
A24: Inalar/Absorver contaminantes | I24: =IF(COUNT(C24:D24)=1,"-->Verifique! Item QTDE ou PESO em branco","-") -> -
A25: Trabalho Sobreposto | I25: =IF(COUNT(C25:D25)=1,"-->Verifique! Item QTDE ou PESO em branco","-") -> -
A26: Ingerir contaminantes | I26: =IF(COUNT(C26:D26)=1,"-->Verifique! Item QTDE ou PESO em branco","-") -> -
A27: Postura inadequada | I27: =IF(COUNT(C27:D27)=1,"-->Verifique! Item QTDE ou PESO em branco","-") -> -
A28: Esforço inadequado | I28: =IF(COUNT(C28:D28)=1,"-->Verifique! Item QTDE ou PESO em branco","-") -> -
A29: Sub-total: | C29: =SUM(C19:C28) -> 0
A30: AÇÃO QUANDO OBSERVADO | C30: Qtd. | D30: Peso | E30: Comentário
A31: Mudança de posição | I31: =IF(COUNT(C31:D31)=1,"-->Verifique! Item QTDE ou PESO em branco","-") -> -
A32: Paraliza a atividade | I32: =IF(COUNT(C32:D32)=1,"-->Verifique! Item QTDE ou PESO em branco","-") -> -
A33: Ajusta o EPI | I33: =IF(COUNT(C33:D33)=1,"-->Verifique! Item QTDE ou PESO em branco","-") -> -
A34: Adequa o serviço | I34: =IF(COUNT(C34:D34)=1,"-->Verifique! Item QTDE ou PESO em branco","-") -> -
A35: Sub-total: | C35: =SUM(C31:C34) -> 0
A36: PROCEDIMENTOS | C36: Qtd. | D36: Peso | E36: Comentário
A37: Inadequados | I37: =IF(COUNT(C37:D37)=1,"-->Verifique! Item QTDE ou PESO em branco","-") -> -
A38: Não existem procedimentos escritos | I38: =IF(COUNT(C38:D38)=1,"-->Verifique! Item QTDE ou PESO em branco","-") -> -
A39: Adequados e não são seguidos | I39: =IF(COUNT(C39:D39)=1,"-->Verifique! Item QTDE ou PESO em branco","-") -> -
A40: Sub-total: | C40: =SUM(C37:C39) -> 0
...

Sheet qua (3)
A1: IDS - INDICADOR DE DESEMPENHO EM SEGURANÇA
A2: Local: | B2: ='seg (1)'!B2 -> CMPC | E2: Auditor Líder: | F2: ='seg (1)'!F2 -> HSE
A3: Contratada: | B3: ='seg (1)'!B3 -> 0 | E3: Auditor:
A4: Subcontratada: | B4: ='seg (1)'!B4 -> 0 | E4: Data:
A5: Acompanhante: | B5: ='seg (1)'!B5 -> 0 | E5: Hora: | G5: Nº de pessoas:
A6: GABARITO DE OBSERVAÇÃO
A7: USO DE EPI´S | C7: Qtd. | D7: Peso | E7: Comentário
A8: Capacete/Jugular | I8: =IF(COUNT(C8:D8)=1,"-->Verifique! Item QTDE ou PESO em branco","-") -> -
A9: Máscara Respiratória | I9: =IF(COUNT(C9:D9)=1,"-->Verifique! Item QTDE ou PESO em branco","-") -> -
A10: Óculos | I10: =IF(COUNT(C10:D10)=1,"-->Verifique! Item QTDE ou PESO em branco","-") -> -
A11: Protetor Facial | I11: =IF(COUNT(C11:D11)=1,"-->Verifique! Item QTDE ou PESO em branco","-") -> -
A12: Protetor Auricular | I12: =IF(COUNT(C12:D12)=1,"-->Verifique! Item QTDE ou PESO em branco","-") -> -
A13: Luvas | I13: =IF(COUNT(C13:D13)=1,"-->Verifique! Item QTDE ou PESO em branco","-") -> -
A14: Avental/jaleco | I14: =IF(COUNT(C14:D14)=1,"-->Verifique! Item QTDE ou PESO em branco","-") -> -
A15: Calçado de Segurança | I15: =IF(COUNT(C15:D15)=1,"-->Verifique! Item QTDE ou PESO em branco","-") -> -
A16: Cinto de Segurança | I16: =IF(COUNT(C16:D16)=1,"-->Verifique! Item QTDE ou PESO em branco","-") -> -
A17: Sub-total: | C17: =SUM(C8:C16) -> 0
A18: POSIÇÃO DAS PESSOAS | C18: Qtd. | D18: Peso | E18: Comentário
A19: Bater contra/Ser atingido por | I19: =IF(COUNT(C19:D19)=1,"-->Verifique! Item QTDE ou PESO em branco","-") -> -
A20: Ficar preso | I20: =IF(COUNT(C20:D20)=1,"-->Verifique! Item QTDE ou PESO em branco","-") -> -
A21: Risco de queda | I21: =IF(COUNT(C21:D21)=1,"-->Verifique! Item QTDE ou PESO em branco","-") -> -
A22: Risco de queimadura | I22: =IF(COUNT(C22:D22)=1,"-->Verifique! Item QTDE ou PESO em branco","-") -> -
A23: Risco de choque elétrico | I23: =IF(COUNT(C23:D23)=1,"-->Verifique! Item QTDE ou PESO em branco","-") -> -
A24: Inalar/Absorver contaminantes | I24: =IF(COUNT(C24:D24)=1,"-->Verifique! Item QTDE ou PESO em branco","-") -> -
A25: Trabalho Sobreposto | I25: =IF(COUNT(C25:D25)=1,"-->Verifique! Item QTDE ou PESO em branco","-") -> -
A26: Ingerir contaminantes | I26: =IF(COUNT(C26:D26)=1,"-->Verifique! Item QTDE ou PESO em branco","-") -> -
A27: Postura inadequada | I27: =IF(COUNT(C27:D27)=1,"-->Verifique! Item QTDE ou PESO em branco","-") -> -
A28: Esforço inadequado | I28: =IF(COUNT(C28:D28)=1,"-->Verifique! Item QTDE ou PESO em branco","-") -> -
A29: Sub-total: | C29: =SUM(C19:C28) -> 0
A30: AÇÃO QUANDO OBSERVADO | C30: Qtd. | D30: Peso | E30: Comentário
A31: Mudança de posição | I31: =IF(COUNT(C31:D31)=1,"-->Verifique! Item QTDE ou PESO em branco","-") -> -
A32: Paraliza a atividade | I32: =IF(COUNT(C32:D32)=1,"-->Verifique! Item QTDE ou PESO em branco","-") -> -
A33: Ajusta o EPI | I33: =IF(COUNT(C33:D33)=1,"-->Verifique! Item QTDE ou PESO em branco","-") -> -
A34: Adequa o serviço | I34: =IF(COUNT(C34:D34)=1,"-->Verifique! Item QTDE ou PESO em branco","-") -> -
A35: Sub-total: | C35: =SUM(C31:C34) -> 0
A36: PROCEDIMENTOS | C36: Qtd. | D36: Peso | E36: Comentário
A37: Inadequados | I37: =IF(COUNT(C37:D37)=1,"-->Verifique! Item QTDE ou PESO em branco","-") -> -
A38: Não existem procedimentos escritos | I38: =IF(COUNT(C38:D38)=1,"-->Verifique! Item QTDE ou PESO em branco","-") -> -
A39: Adequados e não são seguidos | I39: =IF(COUNT(C39:D39)=1,"-->Verifique! Item QTDE ou PESO em branco","-") -> -
A40: Sub-total: | C40: =SUM(C37:C39) -> 0
...

Sheet qui (3)
A1: IDS - INDICADOR DE DESEMPENHO EM SEGURANÇA
A2: Local: | B2: ='seg (1)'!B2 -> CMPC | E2: Auditor Líder: | F2: ='seg (1)'!F2 -> HSE
A3: Contratada: | B3: ='seg (1)'!B3 -> 0 | E3: Auditor:
A4: Subcontratada: | B4: ='seg (1)'!B4 -> 0 | E4: Data:
A5: Acompanhante: | B5: ='seg (1)'!B5 -> 0 | E5: Hora: | G5: Nº de pessoas:
A6: GABARITO DE OBSERVAÇÃO
A7: USO DE EPI´S | C7: Qtd. | D7: Peso | E7: Comentário
A8: Capacete/Jugular | I8: =IF(COUNT(C8:D8)=1,"-->Verifique! Item QTDE ou PESO em branco","-") -> -
A9: Máscara Respiratória | I9: =IF(COUNT(C9:D9)=1,"-->Verifique! Item QTDE ou PESO em branco","-") -> -
A10: Óculos | I10: =IF(COUNT(C10:D10)=1,"-->Verifique! Item QTDE ou PESO em branco","-") -> -
A11: Protetor Facial | I11: =IF(COUNT(C11:D11)=1,"-->Verifique! Item QTDE ou PESO em branco","-") -> -
A12: Protetor Auricular | I12: =IF(COUNT(C12:D12)=1,"-->Verifique! Item QTDE ou PESO em branco","-") -> -
A13: Luvas | I13: =IF(COUNT(C13:D13)=1,"-->Verifique! Item QTDE ou PESO em branco","-") -> -
A14: Avental/jaleco | I14: =IF(COUNT(C14:D14)=1,"-->Verifique! Item QTDE ou PESO em branco","-") -> -
A15: Calçado de Segurança | I15: =IF(COUNT(C15:D15)=1,"-->Verifique! Item QTDE ou PESO em branco","-") -> -
A16: Cinto de Segurança | I16: =IF(COUNT(C16:D16)=1,"-->Verifique! Item QTDE ou PESO em branco","-") -> -
A17: Sub-total: | C17: =SUM(C8:C16) -> 0
A18: POSIÇÃO DAS PESSOAS | C18: Qtd. | D18: Peso | E18: Comentário
A19: Bater contra/Ser atingido por | I19: =IF(COUNT(C19:D19)=1,"-->Verifique! Item QTDE ou PESO em branco","-") -> -
A20: Ficar preso | I20: =IF(COUNT(C20:D20)=1,"-->Verifique! Item QTDE ou PESO em branco","-") -> -
A21: Risco de queda | I21: =IF(COUNT(C21:D21)=1,"-->Verifique! Item QTDE ou PESO em branco","-") -> -
A22: Risco de queimadura | I22: =IF(COUNT(C22:D22)=1,"-->Verifique! Item QTDE ou PESO em branco","-") -> -
A23: Risco de choque elétrico | I23: =IF(COUNT(C23:D23)=1,"-->Verifique! Item QTDE ou PESO em branco","-") -> -
A24: Inalar/Absorver contaminantes | I24: =IF(COUNT(C24:D24)=1,"-->Verifique! Item QTDE ou PESO em branco","-") -> -
A25: Trabalho Sobreposto | I25: =IF(COUNT(C25:D25)=1,"-->Verifique! Item QTDE ou PESO em branco","-") -> -
A26: Ingerir contaminantes | I26: =IF(COUNT(C26:D26)=1,"-->Verifique! Item QTDE ou PESO em branco","-") -> -
A27: Postura inadequada | I27: =IF(COUNT(C27:D27)=1,"-->Verifique! Item QTDE ou PESO em branco","-") -> -
A28: Esforço inadequado | I28: =IF(COUNT(C28:D28)=1,"-->Verifique! Item QTDE ou PESO em branco","-") -> -
A29: Sub-total: | C29: =SUM(C19:C28) -> 0
A30: AÇÃO QUANDO OBSERVADO | C30: Qtd. | D30: Peso | E30: Comentário
A31: Mudança de posição | I31: =IF(COUNT(C31:D31)=1,"-->Verifique! Item QTDE ou PESO em branco","-") -> -
A32: Paraliza a atividade | I32: =IF(COUNT(C32:D32)=1,"-->Verifique! Item QTDE ou PESO em branco","-") -> -
A33: Ajusta o EPI | I33: =IF(COUNT(C33:D33)=1,"-->Verifique! Item QTDE ou PESO em branco","-") -> -
A34: Adequa o serviço | I34: =IF(COUNT(C34:D34)=1,"-->Verifique! Item QTDE ou PESO em branco","-") -> -
A35: Sub-total: | C35: =SUM(C31:C34) -> 0
A36: PROCEDIMENTOS | C36: Qtd. | D36: Peso | E36: Comentário
A37: Inadequados | I37: =IF(COUNT(C37:D37)=1,"-->Verifique! Item QTDE ou PESO em branco","-") -> -
A38: Não existem procedimentos escritos | I38: =IF(COUNT(C38:D38)=1,"-->Verifique! Item QTDE ou PESO em branco","-") -> -
A39: Adequados e não são seguidos | I39: =IF(COUNT(C39:D39)=1,"-->Verifique! Item QTDE ou PESO em branco","-") -> -
A40: Sub-total: | C40: =SUM(C37:C39) -> 0
...

Sheet sex (3)
A1: IDS - INDICADOR DE DESEMPENHO EM SEGURANÇA
A2: Local: | B2: ='seg (1)'!B2 -> CMPC | E2: Auditor Líder: | F2: ='seg (1)'!F2 -> HSE
A3: Contratada: | B3: ='seg (1)'!B3 -> 0 | E3: Auditor:
A4: Subcontratada: | B4: ='seg (1)'!B4 -> 0 | E4: Data:
A5: Acompanhante: | B5: ='seg (1)'!B5 -> 0 | E5: Hora: | G5: Nº de pessoas:
A6: GABARITO DE OBSERVAÇÃO
A7: USO DE EPI´S | C7: Qtd. | D7: Peso | E7: Comentário
A8: Capacete/Jugular | I8: =IF(COUNT(C8:D8)=1,"-->Verifique! Item QTDE ou PESO em branco","-") -> -
A9: Máscara Respiratória | I9: =IF(COUNT(C9:D9)=1,"-->Verifique! Item QTDE ou PESO em branco","-") -> -
A10: Óculos | I10: =IF(COUNT(C10:D10)=1,"-->Verifique! Item QTDE ou PESO em branco","-") -> -
A11: Protetor Facial | I11: =IF(COUNT(C11:D11)=1,"-->Verifique! Item QTDE ou PESO em branco","-") -> -
A12: Protetor Auricular | I12: =IF(COUNT(C12:D12)=1,"-->Verifique! Item QTDE ou PESO em branco","-") -> -
A13: Luvas | I13: =IF(COUNT(C13:D13)=1,"-->Verifique! Item QTDE ou PESO em branco","-") -> -
A14: Avental/jaleco | I14: =IF(COUNT(C14:D14)=1,"-->Verifique! Item QTDE ou PESO em branco","-") -> -
A15: Calçado de Segurança | I15: =IF(COUNT(C15:D15)=1,"-->Verifique! Item QTDE ou PESO em branco","-") -> -
A16: Cinto de Segurança | I16: =IF(COUNT(C16:D16)=1,"-->Verifique! Item QTDE ou PESO em branco","-") -> -
A17: Sub-total: | C17: =SUM(C8:C16) -> 0
A18: POSIÇÃO DAS PESSOAS | C18: Qtd. | D18: Peso | E18: Comentário
A19: Bater contra/Ser atingido por | I19: =IF(COUNT(C19:D19)=1,"-->Verifique! Item QTDE ou PESO em branco","-") -> -
A20: Ficar preso | I20: =IF(COUNT(C20:D20)=1,"-->Verifique! Item QTDE ou PESO em branco","-") -> -
A21: Risco de queda | I21: =IF(COUNT(C21:D21)=1,"-->Verifique! Item QTDE ou PESO em branco","-") -> -
A22: Risco de queimadura | I22: =IF(COUNT(C22:D22)=1,"-->Verifique! Item QTDE ou PESO em branco","-") -> -
A23: Risco de choque elétrico | I23: =IF(COUNT(C23:D23)=1,"-->Verifique! Item QTDE ou PESO em branco","-") -> -
A24: Inalar/Absorver contaminantes | I24: =IF(COUNT(C24:D24)=1,"-->Verifique! Item QTDE ou PESO em branco","-") -> -
A25: Trabalho Sobreposto | I25: =IF(COUNT(C25:D25)=1,"-->Verifique! Item QTDE ou PESO em branco","-") -> -
A26: Ingerir contaminantes | I26: =IF(COUNT(C26:D26)=1,"-->Verifique! Item QTDE ou PESO em branco","-") -> -
A27: Postura inadequada | I27: =IF(COUNT(C27:D27)=1,"-->Verifique! Item QTDE ou PESO em branco","-") -> -
A28: Esforço inadequado | I28: =IF(COUNT(C28:D28)=1,"-->Verifique! Item QTDE ou PESO em branco","-") -> -
A29: Sub-total: | C29: =SUM(C19:C28) -> 0
A30: AÇÃO QUANDO OBSERVADO | C30: Qtd. | D30: Peso | E30: Comentário
A31: Mudança de posição | I31: =IF(COUNT(C31:D31)=1,"-->Verifique! Item QTDE ou PESO em branco","-") -> -
A32: Paraliza a atividade | I32: =IF(COUNT(C32:D32)=1,"-->Verifique! Item QTDE ou PESO em branco","-") -> -
A33: Ajusta o EPI | I33: =IF(COUNT(C33:D33)=1,"-->Verifique! Item QTDE ou PESO em branco","-") -> -
A34: Adequa o serviço | I34: =IF(COUNT(C34:D34)=1,"-->Verifique! Item QTDE ou PESO em branco","-") -> -
A35: Sub-total: | C35: =SUM(C31:C34) -> 0
A36: PROCEDIMENTOS | C36: Qtd. | D36: Peso | E36: Comentário
A37: Inadequados | I37: =IF(COUNT(C37:D37)=1,"-->Verifique! Item QTDE ou PESO em branco","-") -> -
A38: Não existem procedimentos escritos | I38: =IF(COUNT(C38:D38)=1,"-->Verifique! Item QTDE ou PESO em branco","-") -> -
A39: Adequados e não são seguidos | I39: =IF(COUNT(C39:D39)=1,"-->Verifique! Item QTDE ou PESO em branco","-") -> -
A40: Sub-total: | C40: =SUM(C37:C39) -> 0
...

Sheet sab (3)
A1: IDS - INDICADOR DE DESEMPENHO EM SEGURANÇA
